<?xml version='1.0'?>

<!-- choose a name space and start xacro -->
<robot name="scout" xmlns:xacro="http://www.ros.org/wiki/xacro">
  <xacro:include filename="$(find ssam_core)/models/scout/macros.xacro"/>
  <xacro:include filename="$(find ssam_core)/models/scout/parameter.xacro"/>

 <!-- Create a dummy link as base link -->
  <link name='base_link'>
    <pose>0 0 0 0 0 0</pose>
  </link>
  <joint type="fixed" name="base_link_to_chassis">
    <child link="chassis_link"/>
    <parent link="base_link"/>
  </joint>

  <!-- Define the chassis of the differential drive robot, which is our base -->
  <link name='chassis_link'>
    <pose>0 0 0 0 0 0</pose>
    <!-- Define inertial system for the chassis -->
    <inertial>
      <mass value="${m_chassis}"/>
      <xacro:box_inertia m="${m_chassis}" x="${x_chassis}" y="${y_chassis}" z="${z_chassis}"/>
    </inertial>
    <!-- Define collision sorrounding box -->
    <collision name='collision'>
      <origin xyz="0 0 0" rpy=" 0 0 0"/>
      <geometry>
        <box size="${x_chassis} ${y_chassis} ${z_chassis}"/>
      </geometry>
    </collision>
    <!-- Define visualization structure -->
    <visual name='base_link_visual'>
	  <origin xyz="0 0 0" rpy=" 0 0 0"/>
      <geometry>
        <box size="${x_chassis} ${y_chassis} ${z_chassis}"/>
      </geometry>
    </visual>
  </link>

  <!-- Add the wheels for the robot -->
  <xacro:macro name="scout_wheel" params="prefix xReflect yReflect">
    <link name="${prefix}_wheel">
      <collision name="collision">
        <origin xyz="0 0 0" rpy="0 1.5707 1.5707"/>
        <geometry>
          <cylinder radius="${r_wheel}" length="${h_wheel}"/>
        </geometry>
        <surface>
          <friction>
            <ode>
              <mu>1.0</mu>
              <mu2>1.0</mu2>
              <slip1>0.0</slip1>
              <slip2>0.0</slip2>
            </ode>
          </friction>
        </surface>
      </collision>
      <visual name="${prefix}_wheel_visual">
        <origin xyz="0 0 0" rpy="0 1.5707 1.5707"/>
        <geometry>
          <cylinder radius="${r_wheel}" length="${h_wheel}"/>
        </geometry>
      </visual>
      <visual name="${prefix}_wheel_test_ball">
        <origin xyz="0.07 0 0" rpy="0 0 0"/>
        <geometry>
          <sphere radius="${r_wheel/3}"/>
        </geometry>
      </visual>
      <inertial>
        <origin xyz="0 0 0" rpy="0 1.5707 1.5707"/>
        <mass value="${m_wheel}"/>
        <cylinder_inertia m="${m_wheel}" r="${r_wheel}" h="${h_wheel}"/>
        <xacro:cylinder_inertia m="${m_wheel}" r="${r_wheel}" h="${h_wheel}"/>
      </inertial>
    </link>

    <joint type="continuous" name="${prefix}_wheel_hinge">
      <origin xyz="${xReflect*x_chassis/4} ${yReflect*(y_chassis/2+h_wheel/2)} ${r_wheel/2-z_chassis/2}" rpy="0 0 0"/>
      <child link="${prefix}_wheel"/>
      <parent link="base_link"/>
      <axis xyz="0 1 0" rpy="0 0 0"/>
      <limit effort="100" velocity="100"/>
      <joint_properties damping="0.0" friction="0.0"/>
    </joint>
  </xacro:macro>

  <xacro:scout_wheel prefix="left_back" xReflect="-1" yReflect="1"/>
  <xacro:scout_wheel prefix="left_front" xReflect="1" yReflect="1"/>
  <xacro:scout_wheel prefix="right_back" xReflect="-1" yReflect="-1"/>
  <xacro:scout_wheel prefix="right_front" xReflect="1" yReflect="-1"/>

  <link name="camera_link">
    <collision>
      <origin xyz="0 0 0" rpy="0 0 0"/>
      <geometry>
		<box size="${l_camera} ${w_camera} ${h_camera}"/>
      </geometry>
    </collision>
    <visual>
      <origin xyz="0 0 0" rpy="0 0 0"/>
      <geometry>
        <box size="${l_camera} ${w_camera} ${h_camera}"/>
      </geometry>
    </visual>
    <inertial>
      <mass value="1e-5" />
      <origin xyz="0 0 0" rpy="0 0 0"/>
      <inertia ixx="1e-6" ixy="0" ixz="0" iyy="1e-6" iyz="0" izz="1e-6" />
    </inertial>
  </link>
  
  <joint name="camera_joint" type="fixed">
    <origin xyz="${x_camera} ${y_camera} ${z_camera}" rpy="0 0 0"/>
    <parent link="base_link"/>
    <child link="camera_link"/>
  </joint>
  
  <link name="camera_link_optical">
  </link>

  <joint name="camera_optical_joint" type="fixed">
    <origin xyz="0 0 0" rpy="${-pi/2} 0 ${-pi/2}"/>
    <parent link="camera_link"/>
    <child link="camera_link_optical"/>
  </joint>

  <link name="imu_link">
    <pose>0 0 0 0 0 0</pose>
  </link>
  <joint name="base_imu_link" type="fixed">
    <origin xyz="0 0 0" rpy="0 0 0" />
    <parent link="base_link" />
    <child link="imu_link" />
  </joint>

  <transmission name="left_back_wheel_transmission">
    <type>transmission_interface/SimpleTransmission</type>
    <joint name="left_back_wheel_hinge">
      <hardwareInterface>hardware_interface/VelocityJointInterface</hardwareInterface>
    </joint>
    <actuator name="left_back_wheel_motor">
      <hardwareInterface>hardware_interface/VelocityJointInterface</hardwareInterface>
      <mechanicalReduction>1</mechanicalReduction>
    </actuator>
  </transmission>

  <transmission name="right_back_wheel_transmission">
    <type>transmission_interface/SimpleTransmission</type>
    <joint name="right_back_wheel_hinge">
      <hardwareInterface>hardware_interface/VelocityJointInterface</hardwareInterface>
    </joint>
    <actuator name="right_back_wheel_motor">
      <hardwareInterface>hardware_interface/VelocityJointInterface</hardwareInterface>
      <mechanicalReduction>1</mechanicalReduction>
    </actuator>
  </transmission>

  <transmission name="left_front_wheel_transmission">
    <type>transmission_interface/SimpleTransmission</type>
    <joint name="left_front_wheel_hinge">
      <hardwareInterface>hardware_interface/VelocityJointInterface</hardwareInterface>
    </joint>
    <actuator name="left_front_wheel_motor">
      <hardwareInterface>hardware_interface/VelocityJointInterface</hardwareInterface>
      <mechanicalReduction>1</mechanicalReduction>
    </actuator>
  </transmission>

  <transmission name="right_front_wheel_transmission">
    <type>transmission_interface/SimpleTransmission</type>
    <joint name="right_front_wheel_hinge">
      <hardwareInterface>hardware_interface/VelocityJointInterface</hardwareInterface>
    </joint>
    <actuator name="right_front_wheel_motor">
      <hardwareInterface>hardware_interface/VelocityJointInterface</hardwareInterface>
      <mechanicalReduction>1</mechanicalReduction>
    </actuator>
  </transmission>

 </robot>
